[2025-01-23T12:52:22.839+0000] {taskinstance.py:1956} INFO - Dependencies all met for dep_context=non-requeueable deps ti=<TaskInstance: task45_train_models_v2.task45_train_models manual__2025-01-23T12:52:14.086373+00:00 [queued]>
[2025-01-23T12:52:22.855+0000] {taskinstance.py:1956} INFO - Dependencies all met for dep_context=requeueable deps ti=<TaskInstance: task45_train_models_v2.task45_train_models manual__2025-01-23T12:52:14.086373+00:00 [queued]>
[2025-01-23T12:52:22.856+0000] {taskinstance.py:2170} INFO - Starting attempt 1 of 1
[2025-01-23T12:52:22.886+0000] {taskinstance.py:2191} INFO - Executing <Task(PythonOperator): task45_train_models> on 2025-01-23 12:52:14.086373+00:00
[2025-01-23T12:52:22.898+0000] {standard_task_runner.py:60} INFO - Started process 6617 to run task
[2025-01-23T12:52:22.907+0000] {standard_task_runner.py:87} INFO - Running: ['***', 'tasks', 'run', 'task45_train_models_v2', 'task45_train_models', 'manual__2025-01-23T12:52:14.086373+00:00', '--job-id', '77', '--raw', '--subdir', 'DAGS_FOLDER/task45_train_models_v2.py', '--cfg-path', '/tmp/tmpeci2_g7y']
[2025-01-23T12:52:22.909+0000] {standard_task_runner.py:88} INFO - Job 77: Subtask task45_train_models
[2025-01-23T12:52:22.931+0000] {warnings.py:109} WARNING - /home/***/.local/lib/python3.8/site-packages/***/settings.py:194: DeprecationWarning: The sql_alchemy_conn option in [core] has been moved to the sql_alchemy_conn option in [database] - the old setting has been used, but please update your config.
  SQL_ALCHEMY_CONN = conf.get("database", "SQL_ALCHEMY_CONN")

[2025-01-23T12:52:23.024+0000] {task_command.py:423} INFO - Running <TaskInstance: task45_train_models_v2.task45_train_models manual__2025-01-23T12:52:14.086373+00:00 [running]> on host a8cdec4ae828
[2025-01-23T12:52:23.256+0000] {taskinstance.py:2480} INFO - Exporting env vars: AIRFLOW_CTX_DAG_OWNER='***' AIRFLOW_CTX_DAG_ID='task45_train_models_v2' AIRFLOW_CTX_TASK_ID='task45_train_models' AIRFLOW_CTX_EXECUTION_DATE='2025-01-23T12:52:14.086373+00:00' AIRFLOW_CTX_TRY_NUMBER='1' AIRFLOW_CTX_DAG_RUN_ID='manual__2025-01-23T12:52:14.086373+00:00'
[2025-01-23T12:52:23.319+0000] {taskinstance.py:2698} ERROR - Task failed with exception
Traceback (most recent call last):
  File "/home/airflow/.local/lib/python3.8/site-packages/airflow/models/taskinstance.py", line 433, in _execute_task
    result = execute_callable(context=context, **execute_callable_kwargs)
  File "/home/airflow/.local/lib/python3.8/site-packages/airflow/operators/python.py", line 199, in execute
    return_value = self.execute_callable()
  File "/home/airflow/.local/lib/python3.8/site-packages/airflow/operators/python.py", line 216, in execute_callable
    return self.python_callable(*self.op_args, **self.op_kwargs)
  File "/opt/airflow/dags/task45_train_models_v2.py", line 22, in compute_model_score
    target = pd.read_json(target_json, type='series')
TypeError: read_json() got an unexpected keyword argument 'type'
[2025-01-23T12:52:23.341+0000] {taskinstance.py:1138} INFO - Marking task as FAILED. dag_id=task45_train_models_v2, task_id=task45_train_models, execution_date=20250123T125214, start_date=20250123T125222, end_date=20250123T125223
[2025-01-23T12:52:23.364+0000] {standard_task_runner.py:107} ERROR - Failed to execute job 77 for task task45_train_models (read_json() got an unexpected keyword argument 'type'; 6617)
[2025-01-23T12:52:23.416+0000] {local_task_job_runner.py:234} INFO - Task exited with return code 1
[2025-01-23T12:52:23.446+0000] {taskinstance.py:3280} INFO - 0 downstream tasks scheduled from follow-on schedule check
