[2025-01-23T13:59:43.310+0000] {taskinstance.py:1956} INFO - Dependencies all met for dep_context=non-requeueable deps ti=<TaskInstance: task45_train_models_v2.task5_retrain_bestModel manual__2025-01-23T13:59:12.301899+00:00 [queued]>
[2025-01-23T13:59:43.357+0000] {taskinstance.py:1956} INFO - Dependencies all met for dep_context=requeueable deps ti=<TaskInstance: task45_train_models_v2.task5_retrain_bestModel manual__2025-01-23T13:59:12.301899+00:00 [queued]>
[2025-01-23T13:59:43.358+0000] {taskinstance.py:2170} INFO - Starting attempt 1 of 1
[2025-01-23T13:59:43.420+0000] {taskinstance.py:2191} INFO - Executing <Task(PythonOperator): task5_retrain_bestModel> on 2025-01-23 13:59:12.301899+00:00
[2025-01-23T13:59:43.442+0000] {standard_task_runner.py:60} INFO - Started process 9074 to run task
[2025-01-23T13:59:43.467+0000] {standard_task_runner.py:87} INFO - Running: ['***', 'tasks', 'run', 'task45_train_models_v2', 'task5_retrain_bestModel', 'manual__2025-01-23T13:59:12.301899+00:00', '--job-id', '165', '--raw', '--subdir', 'DAGS_FOLDER/task45_train_models_v2.py', '--cfg-path', '/tmp/tmp23dvni9k']
[2025-01-23T13:59:43.469+0000] {standard_task_runner.py:88} INFO - Job 165: Subtask task5_retrain_bestModel
[2025-01-23T13:59:43.530+0000] {warnings.py:109} WARNING - /home/***/.local/lib/python3.8/site-packages/***/settings.py:194: DeprecationWarning: The sql_alchemy_conn option in [core] has been moved to the sql_alchemy_conn option in [database] - the old setting has been used, but please update your config.
  SQL_ALCHEMY_CONN = conf.get("database", "SQL_ALCHEMY_CONN")

[2025-01-23T13:59:43.664+0000] {task_command.py:423} INFO - Running <TaskInstance: task45_train_models_v2.task5_retrain_bestModel manual__2025-01-23T13:59:12.301899+00:00 [running]> on host a8cdec4ae828
[2025-01-23T13:59:44.070+0000] {taskinstance.py:2480} INFO - Exporting env vars: AIRFLOW_CTX_DAG_OWNER='***' AIRFLOW_CTX_DAG_ID='task45_train_models_v2' AIRFLOW_CTX_TASK_ID='task5_retrain_bestModel' AIRFLOW_CTX_EXECUTION_DATE='2025-01-23T13:59:12.301899+00:00' AIRFLOW_CTX_TRY_NUMBER='1' AIRFLOW_CTX_DAG_RUN_ID='manual__2025-01-23T13:59:12.301899+00:00'
[2025-01-23T13:59:44.283+0000] {taskinstance.py:2698} ERROR - Task failed with exception
Traceback (most recent call last):
  File "/home/airflow/.local/lib/python3.8/site-packages/airflow/models/taskinstance.py", line 433, in _execute_task
    result = execute_callable(context=context, **execute_callable_kwargs)
  File "/home/airflow/.local/lib/python3.8/site-packages/airflow/operators/python.py", line 199, in execute
    return_value = self.execute_callable()
  File "/home/airflow/.local/lib/python3.8/site-packages/airflow/operators/python.py", line 216, in execute_callable
    return self.python_callable(*self.op_args, **self.op_kwargs)
  File "/opt/airflow/dags/task45_train_models_v2.py", line 101, in retrain_bestModel
    model.fit(features, target)
AttributeError: 'str' object has no attribute 'fit'
[2025-01-23T13:59:44.299+0000] {taskinstance.py:1138} INFO - Marking task as FAILED. dag_id=task45_train_models_v2, task_id=task5_retrain_bestModel, execution_date=20250123T135912, start_date=20250123T135943, end_date=20250123T135944
[2025-01-23T13:59:44.336+0000] {standard_task_runner.py:107} ERROR - Failed to execute job 165 for task task5_retrain_bestModel ('str' object has no attribute 'fit'; 9074)
[2025-01-23T13:59:44.370+0000] {local_task_job_runner.py:234} INFO - Task exited with return code 1
[2025-01-23T13:59:44.424+0000] {taskinstance.py:3280} INFO - 0 downstream tasks scheduled from follow-on schedule check
