[2025-01-22T23:24:55.016+0000] {taskinstance.py:1956} INFO - Dependencies all met for dep_context=non-requeueable deps ti=<TaskInstance: retrieve_data_from_web.print_date_task manual__2025-01-22T23:24:46.825184+00:00 [queued]>
[2025-01-22T23:24:55.031+0000] {taskinstance.py:1956} INFO - Dependencies all met for dep_context=requeueable deps ti=<TaskInstance: retrieve_data_from_web.print_date_task manual__2025-01-22T23:24:46.825184+00:00 [queued]>
[2025-01-22T23:24:55.032+0000] {taskinstance.py:2170} INFO - Starting attempt 1 of 1
[2025-01-22T23:24:55.058+0000] {taskinstance.py:2191} INFO - Executing <Task(PythonOperator): print_date_task> on 2025-01-22 23:24:46.825184+00:00
[2025-01-22T23:24:55.068+0000] {standard_task_runner.py:60} INFO - Started process 5133 to run task
[2025-01-22T23:24:55.076+0000] {standard_task_runner.py:87} INFO - Running: ['***', 'tasks', 'run', 'retrieve_data_from_web', 'print_date_task', 'manual__2025-01-22T23:24:46.825184+00:00', '--job-id', '2', '--raw', '--subdir', 'DAGS_FOLDER/task1_retrieve_data.py', '--cfg-path', '/tmp/tmpvdrx2pi2']
[2025-01-22T23:24:55.080+0000] {standard_task_runner.py:88} INFO - Job 2: Subtask print_date_task
[2025-01-22T23:24:55.113+0000] {warnings.py:109} WARNING - /home/***/.local/lib/python3.8/site-packages/***/settings.py:194: DeprecationWarning: The sql_alchemy_conn option in [core] has been moved to the sql_alchemy_conn option in [database] - the old setting has been used, but please update your config.
  SQL_ALCHEMY_CONN = conf.get("database", "SQL_ALCHEMY_CONN")

[2025-01-22T23:24:55.170+0000] {task_command.py:423} INFO - Running <TaskInstance: retrieve_data_from_web.print_date_task manual__2025-01-22T23:24:46.825184+00:00 [running]> on host a8cdec4ae828
[2025-01-22T23:24:55.318+0000] {taskinstance.py:2480} INFO - Exporting env vars: AIRFLOW_CTX_DAG_OWNER='***' AIRFLOW_CTX_DAG_ID='retrieve_data_from_web' AIRFLOW_CTX_TASK_ID='print_date_task' AIRFLOW_CTX_EXECUTION_DATE='2025-01-22T23:24:46.825184+00:00' AIRFLOW_CTX_TRY_NUMBER='1' AIRFLOW_CTX_DAG_RUN_ID='manual__2025-01-22T23:24:46.825184+00:00'
[2025-01-22T23:24:55.938+0000] {taskinstance.py:2698} ERROR - Task failed with exception
Traceback (most recent call last):
  File "/home/airflow/.local/lib/python3.8/site-packages/airflow/models/taskinstance.py", line 433, in _execute_task
    result = execute_callable(context=context, **execute_callable_kwargs)
  File "/home/airflow/.local/lib/python3.8/site-packages/airflow/operators/python.py", line 199, in execute
    return_value = self.execute_callable()
  File "/home/airflow/.local/lib/python3.8/site-packages/airflow/operators/python.py", line 216, in execute_callable
    return self.python_callable(*self.op_args, **self.op_kwargs)
  File "/opt/airflow/dags/task1_retrieve_data.py", line 32, in retrieve_data
    json.dump(allData, f)
NameError: name 'json' is not defined
[2025-01-22T23:24:55.953+0000] {taskinstance.py:1138} INFO - Marking task as FAILED. dag_id=retrieve_data_from_web, task_id=print_date_task, execution_date=20250122T232446, start_date=20250122T232455, end_date=20250122T232455
[2025-01-22T23:24:55.977+0000] {standard_task_runner.py:107} ERROR - Failed to execute job 2 for task print_date_task (name 'json' is not defined; 5133)
[2025-01-22T23:24:56.017+0000] {local_task_job_runner.py:234} INFO - Task exited with return code 1
[2025-01-22T23:24:56.060+0000] {taskinstance.py:3280} INFO - 0 downstream tasks scheduled from follow-on schedule check
